2023-08-31 15:48:42,646 [INFO] shopapp.views: Rendering shop index
2023-08-31 15:48:42,810 [INFO] shopapp.views: Rendering shop index
2023-08-31 15:48:42,972 [INFO] shopapp.views: Rendering shop index
2023-08-31 15:48:43,191 [INFO] shopapp.views: Rendering shop index
2023-08-31 15:49:23,669 [INFO] django.utils.autoreload: /home/andrey/python_django/my_site/my_site/settings.py changed, reloading.
2023-08-31 15:49:24,195 [INFO] django.utils.autoreload: Watching for file changes with StatReloader
2023-08-31 15:50:37,737 [INFO] django.utils.autoreload: /home/andrey/python_django/my_site/my_site/settings.py changed, reloading.
2023-08-31 15:50:38,319 [INFO] django.utils.autoreload: Watching for file changes with StatReloader
2023-08-31 15:51:06,941 [INFO] django.utils.autoreload: /home/andrey/python_django/my_site/my_site/settings.py changed, reloading.
2023-08-31 15:51:07,740 [INFO] django.utils.autoreload: Watching for file changes with StatReloader
2023-08-31 16:04:37,077 [INFO] django.utils.autoreload: /home/andrey/python_django/my_site/my_site/settings.py changed, reloading.
2023-08-31 16:04:37,719 [INFO] django.utils.autoreload: Watching for file changes with StatReloader
2023-08-31 16:04:50,931 [INFO] django.utils.autoreload: /home/andrey/python_django/my_site/my_site/settings.py changed, reloading.
2023-08-31 16:04:51,475 [INFO] django.utils.autoreload: Watching for file changes with StatReloader
2023-08-31 16:05:34,612 [INFO] django.utils.autoreload: /home/andrey/python_django/my_site/my_site/settings.py changed, reloading.
2023-08-31 16:05:35,184 [INFO] django.utils.autoreload: Watching for file changes with StatReloader
2023-08-31 16:06:12,194 [INFO] django.utils.autoreload: /home/andrey/python_django/my_site/my_site/settings.py changed, reloading.
2023-08-31 16:06:12,693 [INFO] django.utils.autoreload: Watching for file changes with StatReloader
2023-08-31 16:06:32,745 [INFO] django.utils.autoreload: /home/andrey/python_django/my_site/my_site/settings.py changed, reloading.
2023-08-31 16:06:33,321 [INFO] django.utils.autoreload: Watching for file changes with StatReloader
2023-08-31 16:07:36,806 [INFO] django.utils.autoreload: /home/andrey/python_django/my_site/my_site/urls.py changed, reloading.
2023-08-31 16:07:37,314 [INFO] django.utils.autoreload: Watching for file changes with StatReloader
2023-08-31 16:08:18,554 [INFO] django.utils.autoreload: /home/andrey/python_django/my_site/my_site/urls.py changed, reloading.
2023-08-31 16:08:19,142 [INFO] django.utils.autoreload: Watching for file changes with StatReloader
2023-09-01 18:33:39,398 [INFO] django.utils.autoreload: Watching for file changes with StatReloader
2023-09-01 18:33:43,276 [WARNING] django.request: Not Found: /
2023-09-01 18:33:43,643 [WARNING] django.request: Not Found: /favicon.ico
2023-09-01 18:34:46,625 [INFO] django.utils.autoreload: Watching for file changes with StatReloader
2023-09-01 18:37:43,663 [INFO] django.utils.autoreload: Watching for file changes with StatReloader
2023-09-02 19:52:01,660 [INFO] django.utils.autoreload: Watching for file changes with StatReloader
2023-09-03 12:07:40,676 [INFO] django.utils.autoreload: Watching for file changes with StatReloader
2023-09-03 12:08:54,323 [INFO] django.utils.autoreload: /home/andrey/python_django/my_site/shopapp/views.py changed, reloading.
2023-09-03 12:08:54,911 [INFO] django.utils.autoreload: Watching for file changes with StatReloader
2023-09-03 12:09:24,104 [INFO] django.utils.autoreload: /home/andrey/python_django/my_site/shopapp/views.py changed, reloading.
2023-09-03 12:09:24,732 [INFO] django.utils.autoreload: Watching for file changes with StatReloader
2023-09-03 12:09:36,884 [INFO] django.utils.autoreload: /home/andrey/python_django/my_site/shopapp/views.py changed, reloading.
2023-09-03 12:09:37,392 [INFO] django.utils.autoreload: Watching for file changes with StatReloader
2023-09-03 12:09:59,197 [INFO] django.utils.autoreload: /home/andrey/python_django/my_site/shopapp/views.py changed, reloading.
2023-09-03 12:09:59,818 [INFO] django.utils.autoreload: Watching for file changes with StatReloader
2023-09-03 12:11:31,318 [INFO] django.utils.autoreload: /home/andrey/python_django/my_site/shopapp/views.py changed, reloading.
2023-09-03 12:11:32,025 [INFO] django.utils.autoreload: Watching for file changes with StatReloader
2023-09-03 12:11:33,113 [ERROR] django.request: Internal Server Error: /ru/shop/products/export/
Traceback (most recent call last):
  File "/home/andrey/.local/lib/python3.10/site-packages/django/core/handlers/exception.py", line 56, in inner
    response = get_response(request)
  File "/home/andrey/.local/lib/python3.10/site-packages/django/core/handlers/base.py", line 197, in _get_response
    response = wrapped_callback(request, *callback_args, **callback_kwargs)
  File "/home/andrey/.local/lib/python3.10/site-packages/django/views/generic/base.py", line 103, in view
    return self.dispatch(request, *args, **kwargs)
  File "/home/andrey/.local/lib/python3.10/site-packages/django/views/generic/base.py", line 142, in dispatch
    return handler(request, *args, **kwargs)
  File "/home/andrey/python_django/my_site/shopapp/views.py", line 218, in get
    name = elem["nam"]
KeyError: 'nam'
2023-09-03 12:14:13,615 [INFO] django.utils.autoreload: /home/andrey/python_django/my_site/shopapp/views.py changed, reloading.
2023-09-03 12:14:14,190 [INFO] django.utils.autoreload: Watching for file changes with StatReloader
2023-09-03 12:24:45,424 [INFO] django.utils.autoreload: /home/andrey/python_django/my_site/my_site/settings.py changed, reloading.
2023-09-03 12:24:46,105 [INFO] django.utils.autoreload: Watching for file changes with StatReloader
2023-09-03 12:25:06,944 [INFO] django.utils.autoreload: /home/andrey/python_django/my_site/shopapp/views.py changed, reloading.
2023-09-03 12:25:07,514 [INFO] django.utils.autoreload: Watching for file changes with StatReloader
2023-09-03 12:26:25,037 [ERROR] django.request: Internal Server Error: /ru/shop/products/export/
Traceback (most recent call last):
  File "/home/andrey/.local/lib/python3.10/site-packages/django/core/handlers/exception.py", line 56, in inner
    response = get_response(request)
  File "/home/andrey/.local/lib/python3.10/site-packages/django/core/handlers/base.py", line 197, in _get_response
    response = wrapped_callback(request, *callback_args, **callback_kwargs)
  File "/home/andrey/.local/lib/python3.10/site-packages/sentry_sdk/integrations/django/views.py", line 84, in sentry_wrapped_callback
    return callback(request, *args, **kwargs)
  File "/home/andrey/.local/lib/python3.10/site-packages/django/views/generic/base.py", line 103, in view
    return self.dispatch(request, *args, **kwargs)
  File "/home/andrey/.local/lib/python3.10/site-packages/django/views/generic/base.py", line 142, in dispatch
    return handler(request, *args, **kwargs)
  File "/home/andrey/python_django/my_site/shopapp/views.py", line 218, in get
    name = elem["nam"]
KeyError: 'nam'
2023-09-03 12:27:48,400 [INFO] django.utils.autoreload: Watching for file changes with StatReloader
2023-09-03 12:28:09,664 [INFO] django.utils.autoreload: Watching for file changes with StatReloader
2023-09-03 12:28:38,220 [INFO] django.utils.autoreload: Watching for file changes with StatReloader
2023-09-03 12:28:46,212 [INFO] django.utils.autoreload: /home/andrey/python_django/my_site/shopapp/views.py changed, reloading.
2023-09-03 12:28:46,983 [INFO] django.utils.autoreload: Watching for file changes with StatReloader
2023-09-05 15:59:08,633 [INFO] django.utils.autoreload: Watching for file changes with StatReloader
2023-09-05 16:05:38,715 [INFO] django.utils.autoreload: /home/andrey/python_django/my_site/shopapp/admin.py changed, reloading.
2023-09-05 16:05:39,509 [INFO] django.utils.autoreload: Watching for file changes with StatReloader
2023-09-05 16:05:46,493 [ERROR] django.request: Internal Server Error: /admin/shopapp/product/
Traceback (most recent call last):
  File "/home/andrey/.local/lib/python3.10/site-packages/django/core/handlers/exception.py", line 56, in inner
    response = get_response(request)
  File "/home/andrey/.local/lib/python3.10/site-packages/django/core/handlers/base.py", line 220, in _get_response
    response = response.render()
  File "/home/andrey/.local/lib/python3.10/site-packages/sentry_sdk/integrations/django/views.py", line 38, in sentry_patched_render
    return old_render(self)
  File "/home/andrey/.local/lib/python3.10/site-packages/django/template/response.py", line 114, in render
    self.content = self.rendered_content
  File "/home/andrey/.local/lib/python3.10/site-packages/sentry_sdk/integrations/django/templates.py", line 75, in rendered_content
    return real_rendered_content.fget(self)
  File "/home/andrey/.local/lib/python3.10/site-packages/django/template/response.py", line 92, in rendered_content
    return template.render(context, self._request)
  File "/home/andrey/.local/lib/python3.10/site-packages/django/template/backends/django.py", line 61, in render
    return self.template.render(context)
  File "/home/andrey/.local/lib/python3.10/site-packages/django/template/base.py", line 175, in render
    return self._render(context)
  File "/home/andrey/.local/lib/python3.10/site-packages/django/test/utils.py", line 111, in instrumented_test_render
    return self.nodelist.render(context)
  File "/home/andrey/.local/lib/python3.10/site-packages/django/template/base.py", line 1005, in render
    return SafeString("".join([node.render_annotated(context) for node in self]))
  File "/home/andrey/.local/lib/python3.10/site-packages/django/template/base.py", line 1005, in <listcomp>
    return SafeString("".join([node.render_annotated(context) for node in self]))
  File "/home/andrey/.local/lib/python3.10/site-packages/django/template/base.py", line 966, in render_annotated
    return self.render(context)
  File "/home/andrey/.local/lib/python3.10/site-packages/django/template/loader_tags.py", line 157, in render
    return compiled_parent._render(context)
  File "/home/andrey/.local/lib/python3.10/site-packages/django/test/utils.py", line 111, in instrumented_test_render
    return self.nodelist.render(context)
  File "/home/andrey/.local/lib/python3.10/site-packages/django/template/base.py", line 1005, in render
    return SafeString("".join([node.render_annotated(context) for node in self]))
  File "/home/andrey/.local/lib/python3.10/site-packages/django/template/base.py", line 1005, in <listcomp>
    return SafeString("".join([node.render_annotated(context) for node in self]))
  File "/home/andrey/.local/lib/python3.10/site-packages/django/template/base.py", line 966, in render_annotated
    return self.render(context)
  File "/home/andrey/.local/lib/python3.10/site-packages/django/template/loader_tags.py", line 157, in render
    return compiled_parent._render(context)
  File "/home/andrey/.local/lib/python3.10/site-packages/django/test/utils.py", line 111, in instrumented_test_render
    return self.nodelist.render(context)
  File "/home/andrey/.local/lib/python3.10/site-packages/django/template/base.py", line 1005, in render
    return SafeString("".join([node.render_annotated(context) for node in self]))
  File "/home/andrey/.local/lib/python3.10/site-packages/django/template/base.py", line 1005, in <listcomp>
    return SafeString("".join([node.render_annotated(context) for node in self]))
  File "/home/andrey/.local/lib/python3.10/site-packages/django/template/base.py", line 966, in render_annotated
    return self.render(context)
  File "/home/andrey/.local/lib/python3.10/site-packages/django/template/loader_tags.py", line 157, in render
    return compiled_parent._render(context)
  File "/home/andrey/.local/lib/python3.10/site-packages/django/test/utils.py", line 111, in instrumented_test_render
    return self.nodelist.render(context)
  File "/home/andrey/.local/lib/python3.10/site-packages/django/template/base.py", line 1005, in render
    return SafeString("".join([node.render_annotated(context) for node in self]))
  File "/home/andrey/.local/lib/python3.10/site-packages/django/template/base.py", line 1005, in <listcomp>
    return SafeString("".join([node.render_annotated(context) for node in self]))
  File "/home/andrey/.local/lib/python3.10/site-packages/django/template/base.py", line 966, in render_annotated
    return self.render(context)
  File "/home/andrey/.local/lib/python3.10/site-packages/django/template/loader_tags.py", line 63, in render
    result = block.nodelist.render(context)
  File "/home/andrey/.local/lib/python3.10/site-packages/django/template/base.py", line 1005, in render
    return SafeString("".join([node.render_annotated(context) for node in self]))
  File "/home/andrey/.local/lib/python3.10/site-packages/django/template/base.py", line 1005, in <listcomp>
    return SafeString("".join([node.render_annotated(context) for node in self]))
  File "/home/andrey/.local/lib/python3.10/site-packages/django/template/base.py", line 966, in render_annotated
    return self.render(context)
  File "/home/andrey/.local/lib/python3.10/site-packages/django/template/loader_tags.py", line 63, in render
    result = block.nodelist.render(context)
  File "/home/andrey/.local/lib/python3.10/site-packages/django/template/base.py", line 1005, in render
    return SafeString("".join([node.render_annotated(context) for node in self]))
  File "/home/andrey/.local/lib/python3.10/site-packages/django/template/base.py", line 1005, in <listcomp>
    return SafeString("".join([node.render_annotated(context) for node in self]))
  File "/home/andrey/.local/lib/python3.10/site-packages/django/template/base.py", line 966, in render_annotated
    return self.render(context)
  File "/home/andrey/.local/lib/python3.10/site-packages/django/contrib/admin/templatetags/base.py", line 45, in render
    return super().render(context)
  File "/home/andrey/.local/lib/python3.10/site-packages/django/template/library.py", line 258, in render
    _dict = self.func(*resolved_args, **resolved_kwargs)
  File "/home/andrey/.local/lib/python3.10/site-packages/django/contrib/admin/templatetags/admin_modify.py", line 65, in submit_row
    add = context["add"]
  File "/home/andrey/.local/lib/python3.10/site-packages/django/template/context.py", line 83, in __getitem__
    raise KeyError(key)
KeyError: 'add'
2023-09-05 16:10:30,550 [INFO] django.utils.autoreload: /home/andrey/python_django/my_site/shopapp/admin.py changed, reloading.
2023-09-05 16:10:31,282 [INFO] django.utils.autoreload: Watching for file changes with StatReloader
2023-09-05 16:11:13,612 [INFO] django.utils.autoreload: /home/andrey/python_django/my_site/shopapp/admin.py changed, reloading.
2023-09-05 16:11:14,436 [INFO] django.utils.autoreload: Watching for file changes with StatReloader
2023-09-05 16:11:33,999 [INFO] django.utils.autoreload: /home/andrey/python_django/my_site/shopapp/admin.py changed, reloading.
2023-09-05 16:11:34,749 [INFO] django.utils.autoreload: Watching for file changes with StatReloader
2023-09-05 16:12:08,382 [INFO] django.utils.autoreload: /home/andrey/python_django/my_site/shopapp/admin.py changed, reloading.
2023-09-05 16:12:09,092 [INFO] django.utils.autoreload: Watching for file changes with StatReloader
2023-09-05 16:12:39,235 [INFO] django.utils.autoreload: /home/andrey/python_django/my_site/shopapp/admin.py changed, reloading.
2023-09-05 16:12:39,814 [INFO] django.utils.autoreload: Watching for file changes with StatReloader
2023-09-05 16:13:59,905 [INFO] django.utils.autoreload: /home/andrey/python_django/my_site/shopapp/admin.py changed, reloading.
2023-09-05 16:14:00,683 [INFO] django.utils.autoreload: Watching for file changes with StatReloader
2023-09-05 16:14:40,848 [INFO] django.utils.autoreload: /home/andrey/python_django/my_site/shopapp/admin.py changed, reloading.
2023-09-05 16:14:41,685 [INFO] django.utils.autoreload: Watching for file changes with StatReloader
2023-09-05 16:15:18,949 [INFO] django.utils.autoreload: /home/andrey/python_django/my_site/shopapp/admin.py changed, reloading.
2023-09-05 16:15:19,698 [INFO] django.utils.autoreload: Watching for file changes with StatReloader
2023-09-05 16:16:00,529 [INFO] django.utils.autoreload: /home/andrey/python_django/my_site/shopapp/admin.py changed, reloading.
2023-09-05 16:16:01,267 [INFO] django.utils.autoreload: Watching for file changes with StatReloader
2023-09-05 16:16:24,492 [INFO] django.utils.autoreload: /home/andrey/python_django/my_site/shopapp/admin.py changed, reloading.
2023-09-05 16:16:25,122 [INFO] django.utils.autoreload: Watching for file changes with StatReloader
2023-09-05 16:16:56,445 [INFO] django.utils.autoreload: /home/andrey/python_django/my_site/shopapp/admin.py changed, reloading.
2023-09-05 16:16:57,166 [INFO] django.utils.autoreload: Watching for file changes with StatReloader
2023-09-05 16:17:39,834 [INFO] django.utils.autoreload: /home/andrey/python_django/my_site/shopapp/admin.py changed, reloading.
2023-09-05 16:17:40,543 [INFO] django.utils.autoreload: Watching for file changes with StatReloader
2023-09-05 16:18:05,063 [INFO] django.utils.autoreload: /home/andrey/python_django/my_site/shopapp/admin.py changed, reloading.
2023-09-05 16:18:05,739 [INFO] django.utils.autoreload: Watching for file changes with StatReloader
2023-09-05 16:18:37,404 [INFO] django.utils.autoreload: /home/andrey/python_django/my_site/shopapp/admin.py changed, reloading.
2023-09-05 16:18:38,139 [INFO] django.utils.autoreload: Watching for file changes with StatReloader
2023-09-05 16:18:55,851 [INFO] django.utils.autoreload: /home/andrey/python_django/my_site/shopapp/admin.py changed, reloading.
2023-09-05 16:18:56,512 [INFO] django.utils.autoreload: Watching for file changes with StatReloader
2023-09-05 16:19:38,715 [INFO] django.utils.autoreload: /home/andrey/python_django/my_site/shopapp/admin.py changed, reloading.
2023-09-05 16:19:39,487 [INFO] django.utils.autoreload: Watching for file changes with StatReloader
2023-09-05 16:20:03,651 [INFO] django.utils.autoreload: /home/andrey/python_django/my_site/shopapp/admin.py changed, reloading.
2023-09-05 16:20:04,321 [INFO] django.utils.autoreload: Watching for file changes with StatReloader
2023-09-05 16:20:32,340 [ERROR] django.request: Internal Server Error: /admin/shopapp/product/import-products-csv/
Traceback (most recent call last):
  File "/home/andrey/.local/lib/python3.10/site-packages/django/db/models/fields/__init__.py", line 1715, in to_python
    return decimal.Decimal(value)
decimal.InvalidOperation: [<class 'decimal.ConversionSyntax'>]

During handling of the above exception, another exception occurred:

Traceback (most recent call last):
  File "/home/andrey/.local/lib/python3.10/site-packages/django/core/handlers/exception.py", line 56, in inner
    response = get_response(request)
  File "/home/andrey/.local/lib/python3.10/site-packages/django/core/handlers/base.py", line 197, in _get_response
    response = wrapped_callback(request, *callback_args, **callback_kwargs)
  File "/home/andrey/.local/lib/python3.10/site-packages/sentry_sdk/integrations/django/views.py", line 84, in sentry_wrapped_callback
    return callback(request, *args, **kwargs)
  File "/home/andrey/python_django/my_site/shopapp/admin.py", line 92, in import_csv
    Product.objects.bulk_create(products)
  File "/home/andrey/.local/lib/python3.10/site-packages/django/db/models/manager.py", line 85, in manager_method
    return getattr(self.get_queryset(), name)(*args, **kwargs)
  File "/home/andrey/.local/lib/python3.10/site-packages/django/db/models/query.py", line 816, in bulk_create
    returned_columns = self._batched_insert(
  File "/home/andrey/.local/lib/python3.10/site-packages/django/db/models/query.py", line 1817, in _batched_insert
    self._insert(
  File "/home/andrey/.local/lib/python3.10/site-packages/django/db/models/query.py", line 1791, in _insert
    return query.get_compiler(using=using).execute_sql(returning_fields)
  File "/home/andrey/.local/lib/python3.10/site-packages/django/db/models/sql/compiler.py", line 1659, in execute_sql
    for sql, params in self.as_sql():
  File "/home/andrey/.local/lib/python3.10/site-packages/django/db/models/sql/compiler.py", line 1583, in as_sql
    value_rows = [
  File "/home/andrey/.local/lib/python3.10/site-packages/django/db/models/sql/compiler.py", line 1584, in <listcomp>
    [
  File "/home/andrey/.local/lib/python3.10/site-packages/django/db/models/sql/compiler.py", line 1585, in <listcomp>
    self.prepare_value(field, self.pre_save_val(field, obj))
  File "/home/andrey/.local/lib/python3.10/site-packages/django/db/models/sql/compiler.py", line 1523, in prepare_value
    value = field.get_db_prep_save(value, connection=self.connection)
  File "/home/andrey/.local/lib/python3.10/site-packages/django/db/models/fields/__init__.py", line 1725, in get_db_prep_save
    self.to_python(value), self.max_digits, self.decimal_places
  File "/home/andrey/.local/lib/python3.10/site-packages/django/db/models/fields/__init__.py", line 1717, in to_python
    raise exceptions.ValidationError(
django.core.exceptions.ValidationError: ['Значение “2299,00” должно быть десятичным числом.']
2023-09-05 16:21:18,713 [ERROR] django.request: Internal Server Error: /admin/shopapp/product/import-products-csv/
Traceback (most recent call last):
  File "/home/andrey/.local/lib/python3.10/site-packages/django/db/backends/utils.py", line 89, in _execute
    return self.cursor.execute(sql, params)
  File "/home/andrey/.local/lib/python3.10/site-packages/django/db/backends/sqlite3/base.py", line 357, in execute
    return Database.Cursor.execute(self, query, params)
sqlite3.IntegrityError: NOT NULL constraint failed: shopapp_product.created_by_id

The above exception was the direct cause of the following exception:

Traceback (most recent call last):
  File "/home/andrey/.local/lib/python3.10/site-packages/django/core/handlers/exception.py", line 56, in inner
    response = get_response(request)
  File "/home/andrey/.local/lib/python3.10/site-packages/django/core/handlers/base.py", line 197, in _get_response
    response = wrapped_callback(request, *callback_args, **callback_kwargs)
  File "/home/andrey/.local/lib/python3.10/site-packages/sentry_sdk/integrations/django/views.py", line 84, in sentry_wrapped_callback
    return callback(request, *args, **kwargs)
  File "/home/andrey/python_django/my_site/shopapp/admin.py", line 92, in import_csv
    Product.objects.bulk_create(products)
  File "/home/andrey/.local/lib/python3.10/site-packages/django/db/models/manager.py", line 85, in manager_method
    return getattr(self.get_queryset(), name)(*args, **kwargs)
  File "/home/andrey/.local/lib/python3.10/site-packages/django/db/models/query.py", line 816, in bulk_create
    returned_columns = self._batched_insert(
  File "/home/andrey/.local/lib/python3.10/site-packages/django/db/models/query.py", line 1817, in _batched_insert
    self._insert(
  File "/home/andrey/.local/lib/python3.10/site-packages/django/db/models/query.py", line 1791, in _insert
    return query.get_compiler(using=using).execute_sql(returning_fields)
  File "/home/andrey/.local/lib/python3.10/site-packages/django/db/models/sql/compiler.py", line 1660, in execute_sql
    cursor.execute(sql, params)
  File "/home/andrey/.local/lib/python3.10/site-packages/debug_toolbar/panels/sql/tracking.py", line 252, in execute
    return self._record(super().execute, sql, params)
  File "/home/andrey/.local/lib/python3.10/site-packages/debug_toolbar/panels/sql/tracking.py", line 177, in _record
    return method(sql, params)
  File "/home/andrey/.local/lib/python3.10/site-packages/django/db/backends/utils.py", line 102, in execute
    return super().execute(sql, params)
  File "/home/andrey/.local/lib/python3.10/site-packages/sentry_sdk/integrations/django/__init__.py", line 616, in execute
    return real_execute(self, sql, params)
  File "/home/andrey/.local/lib/python3.10/site-packages/django/db/backends/utils.py", line 67, in execute
    return self._execute_with_wrappers(
  File "/home/andrey/.local/lib/python3.10/site-packages/django/db/backends/utils.py", line 80, in _execute_with_wrappers
    return executor(sql, params, many, context)
  File "/home/andrey/.local/lib/python3.10/site-packages/django/db/backends/utils.py", line 84, in _execute
    with self.db.wrap_database_errors:
  File "/home/andrey/.local/lib/python3.10/site-packages/django/db/utils.py", line 91, in __exit__
    raise dj_exc_value.with_traceback(traceback) from exc_value
  File "/home/andrey/.local/lib/python3.10/site-packages/django/db/backends/utils.py", line 89, in _execute
    return self.cursor.execute(sql, params)
  File "/home/andrey/.local/lib/python3.10/site-packages/django/db/backends/sqlite3/base.py", line 357, in execute
    return Database.Cursor.execute(self, query, params)
django.db.utils.IntegrityError: NOT NULL constraint failed: shopapp_product.created_by_id
2023-09-05 16:22:43,451 [ERROR] django.request: Internal Server Error: /admin/shopapp/product/import-products-csv/
Traceback (most recent call last):
  File "/home/andrey/.local/lib/python3.10/site-packages/django/db/backends/utils.py", line 89, in _execute
    return self.cursor.execute(sql, params)
  File "/home/andrey/.local/lib/python3.10/site-packages/django/db/backends/sqlite3/base.py", line 357, in execute
    return Database.Cursor.execute(self, query, params)
sqlite3.IntegrityError: NOT NULL constraint failed: shopapp_product.created_by_id

The above exception was the direct cause of the following exception:

Traceback (most recent call last):
  File "/home/andrey/.local/lib/python3.10/site-packages/django/core/handlers/exception.py", line 56, in inner
    response = get_response(request)
  File "/home/andrey/.local/lib/python3.10/site-packages/django/core/handlers/base.py", line 197, in _get_response
    response = wrapped_callback(request, *callback_args, **callback_kwargs)
  File "/home/andrey/.local/lib/python3.10/site-packages/sentry_sdk/integrations/django/views.py", line 84, in sentry_wrapped_callback
    return callback(request, *args, **kwargs)
  File "/home/andrey/python_django/my_site/shopapp/admin.py", line 92, in import_csv
    Product.objects.bulk_create(products)
  File "/home/andrey/.local/lib/python3.10/site-packages/django/db/models/manager.py", line 85, in manager_method
    return getattr(self.get_queryset(), name)(*args, **kwargs)
  File "/home/andrey/.local/lib/python3.10/site-packages/django/db/models/query.py", line 816, in bulk_create
    returned_columns = self._batched_insert(
  File "/home/andrey/.local/lib/python3.10/site-packages/django/db/models/query.py", line 1817, in _batched_insert
    self._insert(
  File "/home/andrey/.local/lib/python3.10/site-packages/django/db/models/query.py", line 1791, in _insert
    return query.get_compiler(using=using).execute_sql(returning_fields)
  File "/home/andrey/.local/lib/python3.10/site-packages/django/db/models/sql/compiler.py", line 1660, in execute_sql
    cursor.execute(sql, params)
  File "/home/andrey/.local/lib/python3.10/site-packages/debug_toolbar/panels/sql/tracking.py", line 252, in execute
    return self._record(super().execute, sql, params)
  File "/home/andrey/.local/lib/python3.10/site-packages/debug_toolbar/panels/sql/tracking.py", line 177, in _record
    return method(sql, params)
  File "/home/andrey/.local/lib/python3.10/site-packages/django/db/backends/utils.py", line 102, in execute
    return super().execute(sql, params)
  File "/home/andrey/.local/lib/python3.10/site-packages/sentry_sdk/integrations/django/__init__.py", line 616, in execute
    return real_execute(self, sql, params)
  File "/home/andrey/.local/lib/python3.10/site-packages/django/db/backends/utils.py", line 67, in execute
    return self._execute_with_wrappers(
  File "/home/andrey/.local/lib/python3.10/site-packages/django/db/backends/utils.py", line 80, in _execute_with_wrappers
    return executor(sql, params, many, context)
  File "/home/andrey/.local/lib/python3.10/site-packages/django/db/backends/utils.py", line 84, in _execute
    with self.db.wrap_database_errors:
  File "/home/andrey/.local/lib/python3.10/site-packages/django/db/utils.py", line 91, in __exit__
    raise dj_exc_value.with_traceback(traceback) from exc_value
  File "/home/andrey/.local/lib/python3.10/site-packages/django/db/backends/utils.py", line 89, in _execute
    return self.cursor.execute(sql, params)
  File "/home/andrey/.local/lib/python3.10/site-packages/django/db/backends/sqlite3/base.py", line 357, in execute
    return Database.Cursor.execute(self, query, params)
django.db.utils.IntegrityError: NOT NULL constraint failed: shopapp_product.created_by_id
2023-09-05 17:52:21,426 [INFO] django.utils.autoreload: /home/andrey/python_django/my_site/shopapp/admin.py changed, reloading.
2023-09-05 17:52:22,330 [INFO] django.utils.autoreload: Watching for file changes with StatReloader
2023-09-05 17:52:35,103 [ERROR] django.request: Internal Server Error: /admin/shopapp/product/import-products-csv/
Traceback (most recent call last):
  File "/home/andrey/.local/lib/python3.10/site-packages/django/db/backends/utils.py", line 89, in _execute
    return self.cursor.execute(sql, params)
  File "/home/andrey/.local/lib/python3.10/site-packages/django/db/backends/sqlite3/base.py", line 357, in execute
    return Database.Cursor.execute(self, query, params)
sqlite3.IntegrityError: NOT NULL constraint failed: shopapp_product.created_by_id

The above exception was the direct cause of the following exception:

Traceback (most recent call last):
  File "/home/andrey/.local/lib/python3.10/site-packages/django/core/handlers/exception.py", line 56, in inner
    response = get_response(request)
  File "/home/andrey/.local/lib/python3.10/site-packages/django/core/handlers/base.py", line 197, in _get_response
    response = wrapped_callback(request, *callback_args, **callback_kwargs)
  File "/home/andrey/.local/lib/python3.10/site-packages/sentry_sdk/integrations/django/views.py", line 84, in sentry_wrapped_callback
    return callback(request, *args, **kwargs)
  File "/home/andrey/python_django/my_site/shopapp/admin.py", line 96, in import_csv
    Product.objects.bulk_create(products)
  File "/home/andrey/.local/lib/python3.10/site-packages/django/db/models/manager.py", line 85, in manager_method
    return getattr(self.get_queryset(), name)(*args, **kwargs)
  File "/home/andrey/.local/lib/python3.10/site-packages/django/db/models/query.py", line 816, in bulk_create
    returned_columns = self._batched_insert(
  File "/home/andrey/.local/lib/python3.10/site-packages/django/db/models/query.py", line 1817, in _batched_insert
    self._insert(
  File "/home/andrey/.local/lib/python3.10/site-packages/django/db/models/query.py", line 1791, in _insert
    return query.get_compiler(using=using).execute_sql(returning_fields)
  File "/home/andrey/.local/lib/python3.10/site-packages/django/db/models/sql/compiler.py", line 1660, in execute_sql
    cursor.execute(sql, params)
  File "/home/andrey/.local/lib/python3.10/site-packages/debug_toolbar/panels/sql/tracking.py", line 252, in execute
    return self._record(super().execute, sql, params)
  File "/home/andrey/.local/lib/python3.10/site-packages/debug_toolbar/panels/sql/tracking.py", line 177, in _record
    return method(sql, params)
  File "/home/andrey/.local/lib/python3.10/site-packages/django/db/backends/utils.py", line 102, in execute
    return super().execute(sql, params)
  File "/home/andrey/.local/lib/python3.10/site-packages/sentry_sdk/integrations/django/__init__.py", line 616, in execute
    return real_execute(self, sql, params)
  File "/home/andrey/.local/lib/python3.10/site-packages/django/db/backends/utils.py", line 67, in execute
    return self._execute_with_wrappers(
  File "/home/andrey/.local/lib/python3.10/site-packages/django/db/backends/utils.py", line 80, in _execute_with_wrappers
    return executor(sql, params, many, context)
  File "/home/andrey/.local/lib/python3.10/site-packages/django/db/backends/utils.py", line 84, in _execute
    with self.db.wrap_database_errors:
  File "/home/andrey/.local/lib/python3.10/site-packages/django/db/utils.py", line 91, in __exit__
    raise dj_exc_value.with_traceback(traceback) from exc_value
  File "/home/andrey/.local/lib/python3.10/site-packages/django/db/backends/utils.py", line 89, in _execute
    return self.cursor.execute(sql, params)
  File "/home/andrey/.local/lib/python3.10/site-packages/django/db/backends/sqlite3/base.py", line 357, in execute
    return Database.Cursor.execute(self, query, params)
django.db.utils.IntegrityError: NOT NULL constraint failed: shopapp_product.created_by_id
2023-09-05 17:55:07,825 [INFO] django.utils.autoreload: /home/andrey/python_django/my_site/shopapp/admin.py changed, reloading.
2023-09-05 17:55:08,571 [INFO] django.utils.autoreload: Watching for file changes with StatReloader
2023-09-05 17:55:10,566 [ERROR] django.request: Internal Server Error: /admin/shopapp/product/import-products-csv/
Traceback (most recent call last):
  File "/home/andrey/.local/lib/python3.10/site-packages/django/db/backends/utils.py", line 89, in _execute
    return self.cursor.execute(sql, params)
  File "/home/andrey/.local/lib/python3.10/site-packages/django/db/backends/sqlite3/base.py", line 357, in execute
    return Database.Cursor.execute(self, query, params)
sqlite3.IntegrityError: NOT NULL constraint failed: shopapp_product.created_by_id

The above exception was the direct cause of the following exception:

Traceback (most recent call last):
  File "/home/andrey/.local/lib/python3.10/site-packages/django/core/handlers/exception.py", line 56, in inner
    response = get_response(request)
  File "/home/andrey/.local/lib/python3.10/site-packages/django/core/handlers/base.py", line 197, in _get_response
    response = wrapped_callback(request, *callback_args, **callback_kwargs)
  File "/home/andrey/.local/lib/python3.10/site-packages/sentry_sdk/integrations/django/views.py", line 84, in sentry_wrapped_callback
    return callback(request, *args, **kwargs)
  File "/home/andrey/python_django/my_site/shopapp/admin.py", line 97, in import_csv
    Product.objects.bulk_create(products)
  File "/home/andrey/.local/lib/python3.10/site-packages/django/db/models/manager.py", line 85, in manager_method
    return getattr(self.get_queryset(), name)(*args, **kwargs)
  File "/home/andrey/.local/lib/python3.10/site-packages/django/db/models/query.py", line 816, in bulk_create
    returned_columns = self._batched_insert(
  File "/home/andrey/.local/lib/python3.10/site-packages/django/db/models/query.py", line 1817, in _batched_insert
    self._insert(
  File "/home/andrey/.local/lib/python3.10/site-packages/django/db/models/query.py", line 1791, in _insert
    return query.get_compiler(using=using).execute_sql(returning_fields)
  File "/home/andrey/.local/lib/python3.10/site-packages/django/db/models/sql/compiler.py", line 1660, in execute_sql
    cursor.execute(sql, params)
  File "/home/andrey/.local/lib/python3.10/site-packages/debug_toolbar/panels/sql/tracking.py", line 252, in execute
    return self._record(super().execute, sql, params)
  File "/home/andrey/.local/lib/python3.10/site-packages/debug_toolbar/panels/sql/tracking.py", line 177, in _record
    return method(sql, params)
  File "/home/andrey/.local/lib/python3.10/site-packages/django/db/backends/utils.py", line 102, in execute
    return super().execute(sql, params)
  File "/home/andrey/.local/lib/python3.10/site-packages/sentry_sdk/integrations/django/__init__.py", line 616, in execute
    return real_execute(self, sql, params)
  File "/home/andrey/.local/lib/python3.10/site-packages/django/db/backends/utils.py", line 67, in execute
    return self._execute_with_wrappers(
  File "/home/andrey/.local/lib/python3.10/site-packages/django/db/backends/utils.py", line 80, in _execute_with_wrappers
    return executor(sql, params, many, context)
  File "/home/andrey/.local/lib/python3.10/site-packages/django/db/backends/utils.py", line 84, in _execute
    with self.db.wrap_database_errors:
  File "/home/andrey/.local/lib/python3.10/site-packages/django/db/utils.py", line 91, in __exit__
    raise dj_exc_value.with_traceback(traceback) from exc_value
  File "/home/andrey/.local/lib/python3.10/site-packages/django/db/backends/utils.py", line 89, in _execute
    return self.cursor.execute(sql, params)
  File "/home/andrey/.local/lib/python3.10/site-packages/django/db/backends/sqlite3/base.py", line 357, in execute
    return Database.Cursor.execute(self, query, params)
django.db.utils.IntegrityError: NOT NULL constraint failed: shopapp_product.created_by_id
2023-09-05 17:57:23,577 [INFO] django.utils.autoreload: /home/andrey/python_django/my_site/shopapp/admin.py changed, reloading.
2023-09-05 17:57:24,299 [INFO] django.utils.autoreload: Watching for file changes with StatReloader
2023-09-05 17:58:03,677 [ERROR] django.request: Internal Server Error: /admin/shopapp/product/import-products-csv/
Traceback (most recent call last):
  File "/home/andrey/.local/lib/python3.10/site-packages/django/db/backends/utils.py", line 89, in _execute
    return self.cursor.execute(sql, params)
  File "/home/andrey/.local/lib/python3.10/site-packages/django/db/backends/sqlite3/base.py", line 357, in execute
    return Database.Cursor.execute(self, query, params)
sqlite3.IntegrityError: NOT NULL constraint failed: shopapp_product.created_by_id

The above exception was the direct cause of the following exception:

Traceback (most recent call last):
  File "/home/andrey/.local/lib/python3.10/site-packages/django/core/handlers/exception.py", line 56, in inner
    response = get_response(request)
  File "/home/andrey/.local/lib/python3.10/site-packages/django/core/handlers/base.py", line 197, in _get_response
    response = wrapped_callback(request, *callback_args, **callback_kwargs)
  File "/home/andrey/.local/lib/python3.10/site-packages/sentry_sdk/integrations/django/views.py", line 84, in sentry_wrapped_callback
    return callback(request, *args, **kwargs)
  File "/home/andrey/python_django/my_site/shopapp/admin.py", line 94, in import_csv
    Product.objects.bulk_create(products)
  File "/home/andrey/.local/lib/python3.10/site-packages/django/db/models/manager.py", line 85, in manager_method
    return getattr(self.get_queryset(), name)(*args, **kwargs)
  File "/home/andrey/.local/lib/python3.10/site-packages/django/db/models/query.py", line 816, in bulk_create
    returned_columns = self._batched_insert(
  File "/home/andrey/.local/lib/python3.10/site-packages/django/db/models/query.py", line 1817, in _batched_insert
    self._insert(
  File "/home/andrey/.local/lib/python3.10/site-packages/django/db/models/query.py", line 1791, in _insert
    return query.get_compiler(using=using).execute_sql(returning_fields)
  File "/home/andrey/.local/lib/python3.10/site-packages/django/db/models/sql/compiler.py", line 1660, in execute_sql
    cursor.execute(sql, params)
  File "/home/andrey/.local/lib/python3.10/site-packages/debug_toolbar/panels/sql/tracking.py", line 252, in execute
    return self._record(super().execute, sql, params)
  File "/home/andrey/.local/lib/python3.10/site-packages/debug_toolbar/panels/sql/tracking.py", line 177, in _record
    return method(sql, params)
  File "/home/andrey/.local/lib/python3.10/site-packages/django/db/backends/utils.py", line 102, in execute
    return super().execute(sql, params)
  File "/home/andrey/.local/lib/python3.10/site-packages/sentry_sdk/integrations/django/__init__.py", line 616, in execute
    return real_execute(self, sql, params)
  File "/home/andrey/.local/lib/python3.10/site-packages/django/db/backends/utils.py", line 67, in execute
    return self._execute_with_wrappers(
  File "/home/andrey/.local/lib/python3.10/site-packages/django/db/backends/utils.py", line 80, in _execute_with_wrappers
    return executor(sql, params, many, context)
  File "/home/andrey/.local/lib/python3.10/site-packages/django/db/backends/utils.py", line 84, in _execute
    with self.db.wrap_database_errors:
  File "/home/andrey/.local/lib/python3.10/site-packages/django/db/utils.py", line 91, in __exit__
    raise dj_exc_value.with_traceback(traceback) from exc_value
  File "/home/andrey/.local/lib/python3.10/site-packages/django/db/backends/utils.py", line 89, in _execute
    return self.cursor.execute(sql, params)
  File "/home/andrey/.local/lib/python3.10/site-packages/django/db/backends/sqlite3/base.py", line 357, in execute
    return Database.Cursor.execute(self, query, params)
django.db.utils.IntegrityError: NOT NULL constraint failed: shopapp_product.created_by_id
2023-09-05 18:01:12,586 [INFO] django.utils.autoreload: /home/andrey/python_django/my_site/shopapp/admin.py changed, reloading.
2023-09-05 18:01:13,416 [INFO] django.utils.autoreload: Watching for file changes with StatReloader
2023-09-05 18:01:18,083 [ERROR] django.request: Internal Server Error: /admin/shopapp/product/import-products-csv/
Traceback (most recent call last):
  File "/home/andrey/.local/lib/python3.10/site-packages/django/db/backends/utils.py", line 89, in _execute
    return self.cursor.execute(sql, params)
  File "/home/andrey/.local/lib/python3.10/site-packages/django/db/backends/sqlite3/base.py", line 357, in execute
    return Database.Cursor.execute(self, query, params)
sqlite3.IntegrityError: NOT NULL constraint failed: shopapp_product.created_by_id

The above exception was the direct cause of the following exception:

Traceback (most recent call last):
  File "/home/andrey/.local/lib/python3.10/site-packages/django/core/handlers/exception.py", line 56, in inner
    response = get_response(request)
  File "/home/andrey/.local/lib/python3.10/site-packages/django/core/handlers/base.py", line 197, in _get_response
    response = wrapped_callback(request, *callback_args, **callback_kwargs)
  File "/home/andrey/.local/lib/python3.10/site-packages/sentry_sdk/integrations/django/views.py", line 84, in sentry_wrapped_callback
    return callback(request, *args, **kwargs)
  File "/home/andrey/python_django/my_site/shopapp/admin.py", line 98, in import_csv
    Product.objects.bulk_create(products)
  File "/home/andrey/.local/lib/python3.10/site-packages/django/db/models/manager.py", line 85, in manager_method
    return getattr(self.get_queryset(), name)(*args, **kwargs)
  File "/home/andrey/.local/lib/python3.10/site-packages/django/db/models/query.py", line 816, in bulk_create
    returned_columns = self._batched_insert(
  File "/home/andrey/.local/lib/python3.10/site-packages/django/db/models/query.py", line 1817, in _batched_insert
    self._insert(
  File "/home/andrey/.local/lib/python3.10/site-packages/django/db/models/query.py", line 1791, in _insert
    return query.get_compiler(using=using).execute_sql(returning_fields)
  File "/home/andrey/.local/lib/python3.10/site-packages/django/db/models/sql/compiler.py", line 1660, in execute_sql
    cursor.execute(sql, params)
  File "/home/andrey/.local/lib/python3.10/site-packages/debug_toolbar/panels/sql/tracking.py", line 252, in execute
    return self._record(super().execute, sql, params)
  File "/home/andrey/.local/lib/python3.10/site-packages/debug_toolbar/panels/sql/tracking.py", line 177, in _record
    return method(sql, params)
  File "/home/andrey/.local/lib/python3.10/site-packages/django/db/backends/utils.py", line 102, in execute
    return super().execute(sql, params)
  File "/home/andrey/.local/lib/python3.10/site-packages/sentry_sdk/integrations/django/__init__.py", line 616, in execute
    return real_execute(self, sql, params)
  File "/home/andrey/.local/lib/python3.10/site-packages/django/db/backends/utils.py", line 67, in execute
    return self._execute_with_wrappers(
  File "/home/andrey/.local/lib/python3.10/site-packages/django/db/backends/utils.py", line 80, in _execute_with_wrappers
    return executor(sql, params, many, context)
  File "/home/andrey/.local/lib/python3.10/site-packages/django/db/backends/utils.py", line 84, in _execute
    with self.db.wrap_database_errors:
  File "/home/andrey/.local/lib/python3.10/site-packages/django/db/utils.py", line 91, in __exit__
    raise dj_exc_value.with_traceback(traceback) from exc_value
  File "/home/andrey/.local/lib/python3.10/site-packages/django/db/backends/utils.py", line 89, in _execute
    return self.cursor.execute(sql, params)
  File "/home/andrey/.local/lib/python3.10/site-packages/django/db/backends/sqlite3/base.py", line 357, in execute
    return Database.Cursor.execute(self, query, params)
django.db.utils.IntegrityError: NOT NULL constraint failed: shopapp_product.created_by_id
2023-09-05 18:03:56,894 [INFO] django.utils.autoreload: /home/andrey/python_django/my_site/shopapp/admin.py changed, reloading.
2023-09-05 18:03:57,591 [INFO] django.utils.autoreload: Watching for file changes with StatReloader
2023-09-05 18:03:58,710 [ERROR] django.request: Internal Server Error: /admin/shopapp/product/import-products-csv/
Traceback (most recent call last):
  File "/home/andrey/.local/lib/python3.10/site-packages/django/db/backends/utils.py", line 89, in _execute
    return self.cursor.execute(sql, params)
  File "/home/andrey/.local/lib/python3.10/site-packages/django/db/backends/sqlite3/base.py", line 357, in execute
    return Database.Cursor.execute(self, query, params)
sqlite3.IntegrityError: NOT NULL constraint failed: shopapp_product.created_by_id

The above exception was the direct cause of the following exception:

Traceback (most recent call last):
  File "/home/andrey/.local/lib/python3.10/site-packages/django/core/handlers/exception.py", line 56, in inner
    response = get_response(request)
  File "/home/andrey/.local/lib/python3.10/site-packages/django/core/handlers/base.py", line 197, in _get_response
    response = wrapped_callback(request, *callback_args, **callback_kwargs)
  File "/home/andrey/.local/lib/python3.10/site-packages/sentry_sdk/integrations/django/views.py", line 84, in sentry_wrapped_callback
    return callback(request, *args, **kwargs)
  File "/home/andrey/python_django/my_site/shopapp/admin.py", line 100, in import_csv
    Product.objects.bulk_create(products)
  File "/home/andrey/.local/lib/python3.10/site-packages/django/db/models/manager.py", line 85, in manager_method
    return getattr(self.get_queryset(), name)(*args, **kwargs)
  File "/home/andrey/.local/lib/python3.10/site-packages/django/db/models/query.py", line 816, in bulk_create
    returned_columns = self._batched_insert(
  File "/home/andrey/.local/lib/python3.10/site-packages/django/db/models/query.py", line 1817, in _batched_insert
    self._insert(
  File "/home/andrey/.local/lib/python3.10/site-packages/django/db/models/query.py", line 1791, in _insert
    return query.get_compiler(using=using).execute_sql(returning_fields)
  File "/home/andrey/.local/lib/python3.10/site-packages/django/db/models/sql/compiler.py", line 1660, in execute_sql
    cursor.execute(sql, params)
  File "/home/andrey/.local/lib/python3.10/site-packages/debug_toolbar/panels/sql/tracking.py", line 252, in execute
    return self._record(super().execute, sql, params)
  File "/home/andrey/.local/lib/python3.10/site-packages/debug_toolbar/panels/sql/tracking.py", line 177, in _record
    return method(sql, params)
  File "/home/andrey/.local/lib/python3.10/site-packages/django/db/backends/utils.py", line 102, in execute
    return super().execute(sql, params)
  File "/home/andrey/.local/lib/python3.10/site-packages/sentry_sdk/integrations/django/__init__.py", line 616, in execute
    return real_execute(self, sql, params)
  File "/home/andrey/.local/lib/python3.10/site-packages/django/db/backends/utils.py", line 67, in execute
    return self._execute_with_wrappers(
  File "/home/andrey/.local/lib/python3.10/site-packages/django/db/backends/utils.py", line 80, in _execute_with_wrappers
    return executor(sql, params, many, context)
  File "/home/andrey/.local/lib/python3.10/site-packages/django/db/backends/utils.py", line 84, in _execute
    with self.db.wrap_database_errors:
  File "/home/andrey/.local/lib/python3.10/site-packages/django/db/utils.py", line 91, in __exit__
    raise dj_exc_value.with_traceback(traceback) from exc_value
  File "/home/andrey/.local/lib/python3.10/site-packages/django/db/backends/utils.py", line 89, in _execute
    return self.cursor.execute(sql, params)
  File "/home/andrey/.local/lib/python3.10/site-packages/django/db/backends/sqlite3/base.py", line 357, in execute
    return Database.Cursor.execute(self, query, params)
django.db.utils.IntegrityError: NOT NULL constraint failed: shopapp_product.created_by_id
2023-09-05 18:04:49,050 [INFO] django.utils.autoreload: /home/andrey/python_django/my_site/shopapp/admin.py changed, reloading.
2023-09-05 18:04:49,815 [INFO] django.utils.autoreload: Watching for file changes with StatReloader
2023-09-05 18:04:50,802 [ERROR] django.request: Internal Server Error: /admin/shopapp/product/import-products-csv/
Traceback (most recent call last):
  File "/home/andrey/.local/lib/python3.10/site-packages/django/db/backends/utils.py", line 89, in _execute
    return self.cursor.execute(sql, params)
  File "/home/andrey/.local/lib/python3.10/site-packages/django/db/backends/sqlite3/base.py", line 357, in execute
    return Database.Cursor.execute(self, query, params)
sqlite3.IntegrityError: NOT NULL constraint failed: shopapp_product.created_by_id

The above exception was the direct cause of the following exception:

Traceback (most recent call last):
  File "/home/andrey/.local/lib/python3.10/site-packages/django/core/handlers/exception.py", line 56, in inner
    response = get_response(request)
  File "/home/andrey/.local/lib/python3.10/site-packages/django/core/handlers/base.py", line 197, in _get_response
    response = wrapped_callback(request, *callback_args, **callback_kwargs)
  File "/home/andrey/.local/lib/python3.10/site-packages/sentry_sdk/integrations/django/views.py", line 84, in sentry_wrapped_callback
    return callback(request, *args, **kwargs)
  File "/home/andrey/python_django/my_site/shopapp/admin.py", line 99, in import_csv
    Product.objects.bulk_create(products)
  File "/home/andrey/.local/lib/python3.10/site-packages/django/db/models/manager.py", line 85, in manager_method
    return getattr(self.get_queryset(), name)(*args, **kwargs)
  File "/home/andrey/.local/lib/python3.10/site-packages/django/db/models/query.py", line 816, in bulk_create
    returned_columns = self._batched_insert(
  File "/home/andrey/.local/lib/python3.10/site-packages/django/db/models/query.py", line 1817, in _batched_insert
    self._insert(
  File "/home/andrey/.local/lib/python3.10/site-packages/django/db/models/query.py", line 1791, in _insert
    return query.get_compiler(using=using).execute_sql(returning_fields)
  File "/home/andrey/.local/lib/python3.10/site-packages/django/db/models/sql/compiler.py", line 1660, in execute_sql
    cursor.execute(sql, params)
  File "/home/andrey/.local/lib/python3.10/site-packages/debug_toolbar/panels/sql/tracking.py", line 252, in execute
    return self._record(super().execute, sql, params)
  File "/home/andrey/.local/lib/python3.10/site-packages/debug_toolbar/panels/sql/tracking.py", line 177, in _record
    return method(sql, params)
  File "/home/andrey/.local/lib/python3.10/site-packages/django/db/backends/utils.py", line 102, in execute
    return super().execute(sql, params)
  File "/home/andrey/.local/lib/python3.10/site-packages/sentry_sdk/integrations/django/__init__.py", line 616, in execute
    return real_execute(self, sql, params)
  File "/home/andrey/.local/lib/python3.10/site-packages/django/db/backends/utils.py", line 67, in execute
    return self._execute_with_wrappers(
  File "/home/andrey/.local/lib/python3.10/site-packages/django/db/backends/utils.py", line 80, in _execute_with_wrappers
    return executor(sql, params, many, context)
  File "/home/andrey/.local/lib/python3.10/site-packages/django/db/backends/utils.py", line 84, in _execute
    with self.db.wrap_database_errors:
  File "/home/andrey/.local/lib/python3.10/site-packages/django/db/utils.py", line 91, in __exit__
    raise dj_exc_value.with_traceback(traceback) from exc_value
  File "/home/andrey/.local/lib/python3.10/site-packages/django/db/backends/utils.py", line 89, in _execute
    return self.cursor.execute(sql, params)
  File "/home/andrey/.local/lib/python3.10/site-packages/django/db/backends/sqlite3/base.py", line 357, in execute
    return Database.Cursor.execute(self, query, params)
django.db.utils.IntegrityError: NOT NULL constraint failed: shopapp_product.created_by_id
2023-09-05 18:05:05,911 [INFO] django.utils.autoreload: /home/andrey/python_django/my_site/shopapp/admin.py changed, reloading.
2023-09-05 18:05:06,760 [INFO] django.utils.autoreload: Watching for file changes with StatReloader
2023-09-05 18:05:13,053 [ERROR] django.request: Internal Server Error: /admin/shopapp/product/import-products-csv/
Traceback (most recent call last):
  File "/home/andrey/.local/lib/python3.10/site-packages/django/db/backends/utils.py", line 89, in _execute
    return self.cursor.execute(sql, params)
  File "/home/andrey/.local/lib/python3.10/site-packages/django/db/backends/sqlite3/base.py", line 357, in execute
    return Database.Cursor.execute(self, query, params)
sqlite3.IntegrityError: NOT NULL constraint failed: shopapp_product.created_by_id

The above exception was the direct cause of the following exception:

Traceback (most recent call last):
  File "/home/andrey/.local/lib/python3.10/site-packages/django/core/handlers/exception.py", line 56, in inner
    response = get_response(request)
  File "/home/andrey/.local/lib/python3.10/site-packages/django/core/handlers/base.py", line 197, in _get_response
    response = wrapped_callback(request, *callback_args, **callback_kwargs)
  File "/home/andrey/.local/lib/python3.10/site-packages/sentry_sdk/integrations/django/views.py", line 84, in sentry_wrapped_callback
    return callback(request, *args, **kwargs)
  File "/home/andrey/python_django/my_site/shopapp/admin.py", line 99, in import_csv
    Product.objects.bulk_create(products)
  File "/home/andrey/.local/lib/python3.10/site-packages/django/db/models/manager.py", line 85, in manager_method
    return getattr(self.get_queryset(), name)(*args, **kwargs)
  File "/home/andrey/.local/lib/python3.10/site-packages/django/db/models/query.py", line 816, in bulk_create
    returned_columns = self._batched_insert(
  File "/home/andrey/.local/lib/python3.10/site-packages/django/db/models/query.py", line 1817, in _batched_insert
    self._insert(
  File "/home/andrey/.local/lib/python3.10/site-packages/django/db/models/query.py", line 1791, in _insert
    return query.get_compiler(using=using).execute_sql(returning_fields)
  File "/home/andrey/.local/lib/python3.10/site-packages/django/db/models/sql/compiler.py", line 1660, in execute_sql
    cursor.execute(sql, params)
  File "/home/andrey/.local/lib/python3.10/site-packages/debug_toolbar/panels/sql/tracking.py", line 252, in execute
    return self._record(super().execute, sql, params)
  File "/home/andrey/.local/lib/python3.10/site-packages/debug_toolbar/panels/sql/tracking.py", line 177, in _record
    return method(sql, params)
  File "/home/andrey/.local/lib/python3.10/site-packages/django/db/backends/utils.py", line 102, in execute
    return super().execute(sql, params)
  File "/home/andrey/.local/lib/python3.10/site-packages/sentry_sdk/integrations/django/__init__.py", line 616, in execute
    return real_execute(self, sql, params)
  File "/home/andrey/.local/lib/python3.10/site-packages/django/db/backends/utils.py", line 67, in execute
    return self._execute_with_wrappers(
  File "/home/andrey/.local/lib/python3.10/site-packages/django/db/backends/utils.py", line 80, in _execute_with_wrappers
    return executor(sql, params, many, context)
  File "/home/andrey/.local/lib/python3.10/site-packages/django/db/backends/utils.py", line 84, in _execute
    with self.db.wrap_database_errors:
  File "/home/andrey/.local/lib/python3.10/site-packages/django/db/utils.py", line 91, in __exit__
    raise dj_exc_value.with_traceback(traceback) from exc_value
  File "/home/andrey/.local/lib/python3.10/site-packages/django/db/backends/utils.py", line 89, in _execute
    return self.cursor.execute(sql, params)
  File "/home/andrey/.local/lib/python3.10/site-packages/django/db/backends/sqlite3/base.py", line 357, in execute
    return Database.Cursor.execute(self, query, params)
django.db.utils.IntegrityError: NOT NULL constraint failed: shopapp_product.created_by_id
2023-09-05 18:05:31,038 [ERROR] django.request: Internal Server Error: /admin/shopapp/product/import-products-csv/
Traceback (most recent call last):
  File "/home/andrey/.local/lib/python3.10/site-packages/django/db/backends/utils.py", line 89, in _execute
    return self.cursor.execute(sql, params)
  File "/home/andrey/.local/lib/python3.10/site-packages/django/db/backends/sqlite3/base.py", line 357, in execute
    return Database.Cursor.execute(self, query, params)
sqlite3.IntegrityError: NOT NULL constraint failed: shopapp_product.created_by_id

The above exception was the direct cause of the following exception:

Traceback (most recent call last):
  File "/home/andrey/.local/lib/python3.10/site-packages/django/core/handlers/exception.py", line 56, in inner
    response = get_response(request)
  File "/home/andrey/.local/lib/python3.10/site-packages/django/core/handlers/base.py", line 197, in _get_response
    response = wrapped_callback(request, *callback_args, **callback_kwargs)
  File "/home/andrey/.local/lib/python3.10/site-packages/sentry_sdk/integrations/django/views.py", line 84, in sentry_wrapped_callback
    return callback(request, *args, **kwargs)
  File "/home/andrey/python_django/my_site/shopapp/admin.py", line 99, in import_csv
    Product.objects.bulk_create(products)
  File "/home/andrey/.local/lib/python3.10/site-packages/django/db/models/manager.py", line 85, in manager_method
    return getattr(self.get_queryset(), name)(*args, **kwargs)
  File "/home/andrey/.local/lib/python3.10/site-packages/django/db/models/query.py", line 816, in bulk_create
    returned_columns = self._batched_insert(
  File "/home/andrey/.local/lib/python3.10/site-packages/django/db/models/query.py", line 1817, in _batched_insert
    self._insert(
  File "/home/andrey/.local/lib/python3.10/site-packages/django/db/models/query.py", line 1791, in _insert
    return query.get_compiler(using=using).execute_sql(returning_fields)
  File "/home/andrey/.local/lib/python3.10/site-packages/django/db/models/sql/compiler.py", line 1660, in execute_sql
    cursor.execute(sql, params)
  File "/home/andrey/.local/lib/python3.10/site-packages/debug_toolbar/panels/sql/tracking.py", line 252, in execute
    return self._record(super().execute, sql, params)
  File "/home/andrey/.local/lib/python3.10/site-packages/debug_toolbar/panels/sql/tracking.py", line 177, in _record
    return method(sql, params)
  File "/home/andrey/.local/lib/python3.10/site-packages/django/db/backends/utils.py", line 102, in execute
    return super().execute(sql, params)
  File "/home/andrey/.local/lib/python3.10/site-packages/sentry_sdk/integrations/django/__init__.py", line 616, in execute
    return real_execute(self, sql, params)
  File "/home/andrey/.local/lib/python3.10/site-packages/django/db/backends/utils.py", line 67, in execute
    return self._execute_with_wrappers(
  File "/home/andrey/.local/lib/python3.10/site-packages/django/db/backends/utils.py", line 80, in _execute_with_wrappers
    return executor(sql, params, many, context)
  File "/home/andrey/.local/lib/python3.10/site-packages/django/db/backends/utils.py", line 84, in _execute
    with self.db.wrap_database_errors:
  File "/home/andrey/.local/lib/python3.10/site-packages/django/db/utils.py", line 91, in __exit__
    raise dj_exc_value.with_traceback(traceback) from exc_value
  File "/home/andrey/.local/lib/python3.10/site-packages/django/db/backends/utils.py", line 89, in _execute
    return self.cursor.execute(sql, params)
  File "/home/andrey/.local/lib/python3.10/site-packages/django/db/backends/sqlite3/base.py", line 357, in execute
    return Database.Cursor.execute(self, query, params)
django.db.utils.IntegrityError: NOT NULL constraint failed: shopapp_product.created_by_id
2023-09-05 18:06:25,753 [INFO] django.utils.autoreload: /home/andrey/python_django/my_site/shopapp/admin.py changed, reloading.
2023-09-05 18:06:26,540 [INFO] django.utils.autoreload: Watching for file changes with StatReloader
2023-09-05 18:09:18,067 [INFO] django.utils.autoreload: /home/andrey/python_django/my_site/shopapp/admin.py changed, reloading.
2023-09-05 18:09:18,730 [INFO] django.utils.autoreload: Watching for file changes with StatReloader
2023-09-05 18:09:58,003 [INFO] django.utils.autoreload: /home/andrey/python_django/my_site/shopapp/admin.py changed, reloading.
2023-09-05 18:09:58,511 [INFO] django.utils.autoreload: Watching for file changes with StatReloader
2023-09-05 18:10:05,263 [ERROR] django.request: Internal Server Error: /admin/shopapp/product/import-products-csv/
Traceback (most recent call last):
  File "/home/andrey/.local/lib/python3.10/site-packages/django/db/backends/utils.py", line 89, in _execute
    return self.cursor.execute(sql, params)
  File "/home/andrey/.local/lib/python3.10/site-packages/django/db/backends/sqlite3/base.py", line 357, in execute
    return Database.Cursor.execute(self, query, params)
sqlite3.IntegrityError: NOT NULL constraint failed: shopapp_product.created_by_id

The above exception was the direct cause of the following exception:

Traceback (most recent call last):
  File "/home/andrey/.local/lib/python3.10/site-packages/django/core/handlers/exception.py", line 56, in inner
    response = get_response(request)
  File "/home/andrey/.local/lib/python3.10/site-packages/django/core/handlers/base.py", line 197, in _get_response
    response = wrapped_callback(request, *callback_args, **callback_kwargs)
  File "/home/andrey/.local/lib/python3.10/site-packages/sentry_sdk/integrations/django/views.py", line 84, in sentry_wrapped_callback
    return callback(request, *args, **kwargs)
  File "/home/andrey/python_django/my_site/shopapp/admin.py", line 100, in import_csv
    Product.objects.bulk_create(products)
  File "/home/andrey/.local/lib/python3.10/site-packages/django/db/models/manager.py", line 85, in manager_method
    return getattr(self.get_queryset(), name)(*args, **kwargs)
  File "/home/andrey/.local/lib/python3.10/site-packages/django/db/models/query.py", line 816, in bulk_create
    returned_columns = self._batched_insert(
  File "/home/andrey/.local/lib/python3.10/site-packages/django/db/models/query.py", line 1817, in _batched_insert
    self._insert(
  File "/home/andrey/.local/lib/python3.10/site-packages/django/db/models/query.py", line 1791, in _insert
    return query.get_compiler(using=using).execute_sql(returning_fields)
  File "/home/andrey/.local/lib/python3.10/site-packages/django/db/models/sql/compiler.py", line 1660, in execute_sql
    cursor.execute(sql, params)
  File "/home/andrey/.local/lib/python3.10/site-packages/debug_toolbar/panels/sql/tracking.py", line 252, in execute
    return self._record(super().execute, sql, params)
  File "/home/andrey/.local/lib/python3.10/site-packages/debug_toolbar/panels/sql/tracking.py", line 177, in _record
    return method(sql, params)
  File "/home/andrey/.local/lib/python3.10/site-packages/django/db/backends/utils.py", line 102, in execute
    return super().execute(sql, params)
  File "/home/andrey/.local/lib/python3.10/site-packages/sentry_sdk/integrations/django/__init__.py", line 616, in execute
    return real_execute(self, sql, params)
  File "/home/andrey/.local/lib/python3.10/site-packages/django/db/backends/utils.py", line 67, in execute
    return self._execute_with_wrappers(
  File "/home/andrey/.local/lib/python3.10/site-packages/django/db/backends/utils.py", line 80, in _execute_with_wrappers
    return executor(sql, params, many, context)
  File "/home/andrey/.local/lib/python3.10/site-packages/django/db/backends/utils.py", line 84, in _execute
    with self.db.wrap_database_errors:
  File "/home/andrey/.local/lib/python3.10/site-packages/django/db/utils.py", line 91, in __exit__
    raise dj_exc_value.with_traceback(traceback) from exc_value
  File "/home/andrey/.local/lib/python3.10/site-packages/django/db/backends/utils.py", line 89, in _execute
    return self.cursor.execute(sql, params)
  File "/home/andrey/.local/lib/python3.10/site-packages/django/db/backends/sqlite3/base.py", line 357, in execute
    return Database.Cursor.execute(self, query, params)
django.db.utils.IntegrityError: NOT NULL constraint failed: shopapp_product.created_by_id
2023-09-05 18:13:19,053 [INFO] django.utils.autoreload: /home/andrey/python_django/my_site/shopapp/admin.py changed, reloading.
2023-09-05 18:13:19,736 [INFO] django.utils.autoreload: Watching for file changes with StatReloader
2023-09-05 18:14:16,570 [INFO] django.utils.autoreload: /home/andrey/python_django/my_site/shopapp/admin.py changed, reloading.
2023-09-05 18:14:17,294 [INFO] django.utils.autoreload: Watching for file changes with StatReloader
2023-09-05 18:26:11,681 [INFO] django.utils.autoreload: /home/andrey/python_django/my_site/shopapp/admin.py changed, reloading.
2023-09-05 18:26:12,500 [INFO] django.utils.autoreload: Watching for file changes with StatReloader
2023-09-05 18:26:25,339 [ERROR] django.request: Internal Server Error: /admin/shopapp/product/import-products-csv/
Traceback (most recent call last):
  File "/home/andrey/.local/lib/python3.10/site-packages/django/db/backends/utils.py", line 89, in _execute
    return self.cursor.execute(sql, params)
  File "/home/andrey/.local/lib/python3.10/site-packages/django/db/backends/sqlite3/base.py", line 357, in execute
    return Database.Cursor.execute(self, query, params)
sqlite3.IntegrityError: NOT NULL constraint failed: shopapp_product.created_by_id

The above exception was the direct cause of the following exception:

Traceback (most recent call last):
  File "/home/andrey/.local/lib/python3.10/site-packages/django/core/handlers/exception.py", line 56, in inner
    response = get_response(request)
  File "/home/andrey/.local/lib/python3.10/site-packages/django/core/handlers/base.py", line 197, in _get_response
    response = wrapped_callback(request, *callback_args, **callback_kwargs)
  File "/home/andrey/.local/lib/python3.10/site-packages/sentry_sdk/integrations/django/views.py", line 84, in sentry_wrapped_callback
    return callback(request, *args, **kwargs)
  File "/home/andrey/python_django/my_site/shopapp/admin.py", line 99, in import_csv
    Product.objects.bulk_create(products)
  File "/home/andrey/.local/lib/python3.10/site-packages/django/db/models/manager.py", line 85, in manager_method
    return getattr(self.get_queryset(), name)(*args, **kwargs)
  File "/home/andrey/.local/lib/python3.10/site-packages/django/db/models/query.py", line 816, in bulk_create
    returned_columns = self._batched_insert(
  File "/home/andrey/.local/lib/python3.10/site-packages/django/db/models/query.py", line 1817, in _batched_insert
    self._insert(
  File "/home/andrey/.local/lib/python3.10/site-packages/django/db/models/query.py", line 1791, in _insert
    return query.get_compiler(using=using).execute_sql(returning_fields)
  File "/home/andrey/.local/lib/python3.10/site-packages/django/db/models/sql/compiler.py", line 1660, in execute_sql
    cursor.execute(sql, params)
  File "/home/andrey/.local/lib/python3.10/site-packages/debug_toolbar/panels/sql/tracking.py", line 252, in execute
    return self._record(super().execute, sql, params)
  File "/home/andrey/.local/lib/python3.10/site-packages/debug_toolbar/panels/sql/tracking.py", line 177, in _record
    return method(sql, params)
  File "/home/andrey/.local/lib/python3.10/site-packages/django/db/backends/utils.py", line 102, in execute
    return super().execute(sql, params)
  File "/home/andrey/.local/lib/python3.10/site-packages/sentry_sdk/integrations/django/__init__.py", line 616, in execute
    return real_execute(self, sql, params)
  File "/home/andrey/.local/lib/python3.10/site-packages/django/db/backends/utils.py", line 67, in execute
    return self._execute_with_wrappers(
  File "/home/andrey/.local/lib/python3.10/site-packages/django/db/backends/utils.py", line 80, in _execute_with_wrappers
    return executor(sql, params, many, context)
  File "/home/andrey/.local/lib/python3.10/site-packages/django/db/backends/utils.py", line 84, in _execute
    with self.db.wrap_database_errors:
  File "/home/andrey/.local/lib/python3.10/site-packages/django/db/utils.py", line 91, in __exit__
    raise dj_exc_value.with_traceback(traceback) from exc_value
  File "/home/andrey/.local/lib/python3.10/site-packages/django/db/backends/utils.py", line 89, in _execute
    return self.cursor.execute(sql, params)
  File "/home/andrey/.local/lib/python3.10/site-packages/django/db/backends/sqlite3/base.py", line 357, in execute
    return Database.Cursor.execute(self, query, params)
django.db.utils.IntegrityError: NOT NULL constraint failed: shopapp_product.created_by_id
2023-09-05 19:10:28,244 [INFO] django.utils.autoreload: /home/andrey/python_django/my_site/shopapp/admin.py changed, reloading.
2023-09-05 19:10:29,032 [INFO] django.utils.autoreload: Watching for file changes with StatReloader
2023-09-06 18:25:46,875 [INFO] django.utils.autoreload: /home/andrey/python_django/my_site/shopapp/admin.py changed, reloading.
2023-09-06 18:25:47,641 [INFO] django.utils.autoreload: Watching for file changes with StatReloader
2023-09-06 18:27:31,369 [ERROR] django.request: Internal Server Error: /admin/shopapp/product/import-products-csv/
Traceback (most recent call last):
  File "/home/andrey/.local/lib/python3.10/site-packages/django/core/handlers/exception.py", line 56, in inner
    response = get_response(request)
  File "/home/andrey/.local/lib/python3.10/site-packages/django/core/handlers/base.py", line 197, in _get_response
    response = wrapped_callback(request, *callback_args, **callback_kwargs)
  File "/home/andrey/.local/lib/python3.10/site-packages/sentry_sdk/integrations/django/views.py", line 84, in sentry_wrapped_callback
    return callback(request, *args, **kwargs)
  File "/home/andrey/python_django/my_site/shopapp/admin.py", line 90, in import_csv
    products = [
  File "/home/andrey/python_django/my_site/shopapp/admin.py", line 91, in <listcomp>
    Product(**row)
  File "/home/andrey/.local/lib/python3.10/site-packages/django/db/models/base.py", line 541, in __init__
    _setattr(self, field.name, rel_obj)
  File "/home/andrey/.local/lib/python3.10/site-packages/django/db/models/fields/related_descriptors.py", line 237, in __set__
    raise ValueError(
ValueError: Cannot assign "'1'": "Product.created_by" must be a "User" instance.
2023-09-06 18:28:10,976 [ERROR] django.request: Internal Server Error: /admin/shopapp/product/import-products-csv/
Traceback (most recent call last):
  File "/home/andrey/.local/lib/python3.10/site-packages/django/core/handlers/exception.py", line 56, in inner
    response = get_response(request)
  File "/home/andrey/.local/lib/python3.10/site-packages/django/core/handlers/base.py", line 197, in _get_response
    response = wrapped_callback(request, *callback_args, **callback_kwargs)
  File "/home/andrey/.local/lib/python3.10/site-packages/sentry_sdk/integrations/django/views.py", line 84, in sentry_wrapped_callback
    return callback(request, *args, **kwargs)
  File "/home/andrey/python_django/my_site/shopapp/admin.py", line 90, in import_csv
    products = [
  File "/home/andrey/python_django/my_site/shopapp/admin.py", line 91, in <listcomp>
    Product(**row)
  File "/home/andrey/.local/lib/python3.10/site-packages/django/db/models/base.py", line 541, in __init__
    _setattr(self, field.name, rel_obj)
  File "/home/andrey/.local/lib/python3.10/site-packages/django/db/models/fields/related_descriptors.py", line 237, in __set__
    raise ValueError(
ValueError: Cannot assign "'admin'": "Product.created_by" must be a "User" instance.
2023-09-06 18:28:40,207 [ERROR] django.request: Internal Server Error: /admin/shopapp/product/import-products-csv/
Traceback (most recent call last):
  File "/home/andrey/.local/lib/python3.10/site-packages/django/core/handlers/exception.py", line 56, in inner
    response = get_response(request)
  File "/home/andrey/.local/lib/python3.10/site-packages/django/core/handlers/base.py", line 197, in _get_response
    response = wrapped_callback(request, *callback_args, **callback_kwargs)
  File "/home/andrey/.local/lib/python3.10/site-packages/sentry_sdk/integrations/django/views.py", line 84, in sentry_wrapped_callback
    return callback(request, *args, **kwargs)
  File "/home/andrey/python_django/my_site/shopapp/admin.py", line 90, in import_csv
    products = [
  File "/home/andrey/python_django/my_site/shopapp/admin.py", line 91, in <listcomp>
    Product(**row)
  File "/home/andrey/.local/lib/python3.10/site-packages/django/db/models/base.py", line 541, in __init__
    _setattr(self, field.name, rel_obj)
  File "/home/andrey/.local/lib/python3.10/site-packages/django/db/models/fields/related_descriptors.py", line 237, in __set__
    raise ValueError(
ValueError: Cannot assign "'1'": "Product.created_by" must be a "User" instance.
2023-09-06 18:29:54,751 [ERROR] django.request: Internal Server Error: /admin/shopapp/product/import-products-csv/
Traceback (most recent call last):
  File "/home/andrey/.local/lib/python3.10/site-packages/django/core/handlers/exception.py", line 56, in inner
    response = get_response(request)
  File "/home/andrey/.local/lib/python3.10/site-packages/django/core/handlers/base.py", line 197, in _get_response
    response = wrapped_callback(request, *callback_args, **callback_kwargs)
  File "/home/andrey/.local/lib/python3.10/site-packages/sentry_sdk/integrations/django/views.py", line 84, in sentry_wrapped_callback
    return callback(request, *args, **kwargs)
  File "/home/andrey/python_django/my_site/shopapp/admin.py", line 90, in import_csv
    products = [
  File "/home/andrey/python_django/my_site/shopapp/admin.py", line 91, in <listcomp>
    Product(**row)
  File "/home/andrey/.local/lib/python3.10/site-packages/django/db/models/base.py", line 541, in __init__
    _setattr(self, field.name, rel_obj)
  File "/home/andrey/.local/lib/python3.10/site-packages/django/db/models/fields/related_descriptors.py", line 237, in __set__
    raise ValueError(
ValueError: Cannot assign "'1'": "Product.created_by" must be a "User" instance.
2023-09-06 18:30:20,174 [ERROR] django.request: Internal Server Error: /admin/shopapp/product/import-products-csv/
Traceback (most recent call last):
  File "/home/andrey/.local/lib/python3.10/site-packages/django/core/handlers/exception.py", line 56, in inner
    response = get_response(request)
  File "/home/andrey/.local/lib/python3.10/site-packages/django/core/handlers/base.py", line 197, in _get_response
    response = wrapped_callback(request, *callback_args, **callback_kwargs)
  File "/home/andrey/.local/lib/python3.10/site-packages/sentry_sdk/integrations/django/views.py", line 84, in sentry_wrapped_callback
    return callback(request, *args, **kwargs)
  File "/home/andrey/python_django/my_site/shopapp/admin.py", line 90, in import_csv
    products = [
  File "/home/andrey/python_django/my_site/shopapp/admin.py", line 91, in <listcomp>
    Product(**row)
  File "/home/andrey/.local/lib/python3.10/site-packages/django/db/models/base.py", line 541, in __init__
    _setattr(self, field.name, rel_obj)
  File "/home/andrey/.local/lib/python3.10/site-packages/django/db/models/fields/related_descriptors.py", line 237, in __set__
    raise ValueError(
ValueError: Cannot assign "'admin'": "Product.created_by" must be a "User" instance.
2023-09-06 18:31:24,318 [INFO] django.utils.autoreload: /home/andrey/python_django/my_site/shopapp/admin.py changed, reloading.
2023-09-06 18:31:25,077 [INFO] django.utils.autoreload: Watching for file changes with StatReloader
